Workbook

Sheet Аэрофлот
A1: Отчет о финансовом положении | I1: Отчет о прибылях и убытках
A2: на 31 декабря 202X года в миллионах рублей | I2: за 202X год в миллионах рублей, если не указано иное
B3: 2020 г. | C3: 2021 г. | D3: 2023 г. | E3: 2024 г. | J3: 2020 г. | K3: 2021 г. | L3: 2023 г. | M3: 2024 г.
A4: АКТИВЫ | I4: Выручка от перевозок | J4: 270476 | K4: 457219 | L4: 596579 | M4: 838980
A5: Оборотные активы | I5: Прочая выручка | J5: 31706 | K5: 34514 | L5: 15615 | M5: 17805
A6: Денежные средства и их эквиваленты | B6: 88944 | C6: 74180 | D6: 83117 | E6: 67814 | I6: Выручка | J6: 302182 | K6: 491733 | L6: 612194 | M6: 856785
A7: Краткосрочные финансовые инвестиции | B7: 4831 | C7: 19573 | D7: 34009 | E7: 37622
A8: Дебиторская задолженность и предоплаты | B8: 67051 | C8: 73213 | D8: 82262 | E8: 87450 | I8: Операционные расходы, за исключением расходов на оплату труда и амортизации | J8: -222070 | K8: -326216 | L8: -411345 | M8: -582213
A9: Предоплата по текущему налогу на прибыль | B9: 469 | C9: 153 | D9: 3521 | E9: 1484 | I9: Расходы на оплату труда | J9: -65445 | K9: -68439 | L9: -77447 | M9: -99848
A10: Страховые депозиты по аренде воздушных судов | B10: 2739 | C10: 3103 | D10: 1827 | E10: 1485 | I10: Амортизация | J10: -118633 | K10: -120506 | L10: -135958 | M10: -113972
A11: Расходные запчасти и запасы | B11: 16889 | C11: 17911 | D11: 31895 | E11: 57728 | I11: Прочие операционные доходы/(расходы), нетто | J11: 11813 | K11: 18413 | L11: 194809 | M11: 38785
A12: Краткосрочные финансовые активы по договорам аренды | B12: 4159 | C12: 2211 | D12: 14171 | E12: 154 | I12: Операционные расходы | J12: -394335 | K12: -496748 | L12: -429941 | M12: -757248
A13: Итого оборотные активы | B13: 185082 | C13: 190344 | D13: 250802 | E13: 253737
I14: Прибыль / убыток от операционной деятельности | J14: -92153 | K14: -5015 | L14: 182253 | M14: 99537
A15: Внеоборотные активы | I15: Прибыль / убыток от обесценения и изменения справедливой стоимости инвестиций, нетто | J15: -557 | K15: -265 | L15: 471 | M15: 614
A16: Активы в форме права пользования | B16: 635406 | C16: 725421 | D16: 619883 | E16: 557557 | I16: Финансовые доходы | J16: 4938 | K16: 12331 | L16: 15968 | M16: 22464
A17: Основные средства | B17: 19825 | C17: 19893 | D17: 104922 | E17: 159838 | I17: Финансовые расходы | J17: -47252 | K17: -41407 | L17: -210060 | M17: -79796
A18: Предоплата за воздушные суда | B18: 27275 | C18: 12743 | I18: Реализация результата хеджирования | J18: -13254 | K18: -8291 | L18: - | M18: -2002
A19: Отложенные налоговые активы | B19: 75430 | C19: 85531 | D19: 93080 | E19: 130228 | I19: Доля в финансовых результатах ассоциированных компаний | J19: -143 | K19: 153 | L19: 18 | M19: 2437
A20: Долгосрочные финансовые инвестиции | B20: 5464 | C20: 5360 | D20: 5335 | E20: 6123 | I20: Результат от выбытия дочерних компаний | J20: -5066 | K20: - | L20: - | M20: -1045
A21: Нематериальные активы | B21: 2414 | C21: 3221 | D21: 7475 | E21: 21245 | I21: Убыток до налогообложения | J21: -153487 | K21: -42494 | L21: -11350 | M21: 42209
A22: Долгосрочные финансовые активы по договорам аренды | B22: 18606 | C22: 25467 | D22: 9800 | I22: Налог на прибыль | J22: 30279 | K22: 8034 | L22: -2671 | M22: 12811
A23: Страховые депозиты по аренде воздушных судов | B23: 1867 | C23: 1934 | D23: 139 | E23: 139
A24: Инвестиции в ассоциированные компании | B24: 419 | C24: 538 | D24: 518 | E24: 1541 | I24: УБЫТОК / ПРИБЫЛЬ ЗА ГОД | J24: -123208 | K24: -34460 | L24: -14021 | M24: 55020
A25: Прочие внеоборотные активы | B25: 44416 | C25: 38998 | D25: 22060 | E25: 26488 | I25: Приходящийся на:
A26: Итого внеоборотные активы | B26: 831122 | C26: 919106 | D26: 863212 | E26: 903159 | I26: Акционеров Компании | J26: -117613 | K26: -34106 | L26: -8862 | M26: 58501
I27: Держателей неконтролирующих долей участия | J27: -5595 | K27: -354 | L27: -5159 | M27: -3481
A28: ИТОГО АКТИВЫ | B28: 1016204 | C28: 1109450 | D28: 1114014 | E28: 1156896
I30: ИСТОЧНИКИ
A31: ОБЯЗАТЕЛЬСТВА И КАПИТАЛ | I31: Отчет о прибылях и убытках и отчет о финансовом положении - | J31: https://ir.aeroflot.ru/reporting/financial-results/ifrs/
A33: Краткосрочные обязательства
A34: Кредиторская задолженность и начисленные обязательства | B34: 52186 | C34: 63211 | D34: 98913 | E34: 116717
A35: Незаработанная транспортная выручка | B35: 44622 | C35: 54837 | D35: 45571 | E35: 64774
A36: Отложенная выручка по программе премирования пассажиров | B36: 1929 | C36: 2043 | D36: 2775 | E36: 15767
A37: Резервы под обязательства | B37: 20859 | C37: 27252 | D37: 42386 | E37: 50711
A38: Обязательства по аренде | B38: 126761 | C38: 107604 | D38: 104876 | E38: 140596
A39: Краткосрочные кредиты и займы и краткосрочная часть долгосрочных кредитов и займов | B39: 34924 | C39: 17500 | D39: 44178 | E39: 19746
A40: Обязательства по текущему налогу на прибыль | B40: 4 | C40: 141 | D40: 905 | E40: 754
A41: Итого краткосрочные обязательства | B41: 281285 | C41: 272588 | D41: 339604 | E41: 409065
A43: Долгосрочные обязательства
...

Sheet TurkishAirlines
A1: Отчет о финансовом положении | H1: Отчет о прибылях и убытках
A2: на 31 декабря 202X года в миллионах рублей | H2: за 202X год в миллионах рублей, если не указано иное
B3: 2020 г. | C3: 2021 г. | D3: 2023 г. | E3: 2024 г. | I3: 2020 г. | J3: 2021 г. | K3: 2023 г. | L3: 2024 г.
A4: АКТИВЫ | H4: ПРИБЫЛЬ ИЛИ УБЫТОК
A6: ВНЕОБОРОТНЫЕ АКТИВЫ | H6: Выручка | I6: 498316 | J6: 790764 | K6: 1905722 | L6: 2312238
A7: Финансовые вложения | B7: 5550 | C7: 6512 | D7: 36218 | E7: 113526 | H7: Себестоимость продаж | I7: -471972 | J7: -615828 | K7: -1461460 | L7: -1871394
A8: Прочая дебиторская задолженность | H8: ВАЛОВАЯ ПРИБЫЛЬ | I8: 26344 | J8: 174936 | K8: 444262 | L8: 440844
A9: Аффилированные лица | B9: - | C9: - | D9: - | E9: 1224
A10: Третьи стороны | B10: 88800 | C10: 64084 | D10: 126945 | E10: 127704 | H10: Общие и административные расходы | I10: -16206 | J10: -18796 | K10: -40859 | L10: -57528
A11: Инвестиции, учитываемые методом долевого участия | B11: 18944 | C11: 17538 | D11: 45227 | E11: 65688 | H11: Коммерческие и маркетинговые расходы | I11: -49358 | J11: -61790 | K11: -160160 | L11: -187476
A12: Инвестиционная собственность | B12: - | C12: - | D12: 3913 | E12: 4386 | H12: Прочие операционные доходы | I12: 24420 | J12: 12876 | K12: 46319 | L12: 61812
A13: Основные средства | B13: 306730 | C13: 322936 | D13: 552825 | E13: 719610 | H13: Прочие операционные расходы | I13: -4070 | J13: -2590 | K13: -29393 | L13: -11526
A14: Активы в форме права пользования | B14: 1093498 | C14: 1118140 | D14: 1540448 | E14: 1797750 | H14: ОПЕРАЦИОННАЯ ПРИБЫЛЬ / УБЫТОК ДО УЧЕТА ИНВЕСТИЦИОННОЙ ДЕЯТЕЛЬНОСТИ | I14: -18870 | J14: 104636 | K14: 260169 | L14: 246126
A15: Нематериальные активы
A16: Прочие нематериальные активы | B16: 6586 | C16: 6068 | D16: 7917 | E16: 11424 | H16: Доходы от инвестиционной деятельности | I16: 14060 | J16: 15318 | K16: 84903 | L16: 170136
A17: Гудвил | B17: 888 | C17: 888 | D17: 2457 | E17: 2754 | H17: Расходы от инвестиционной деятельности | I17: -814 | J17: -518 | K17: -5915 | L17: -7650
A18: Расходы будущих периодов | B18: 59052 | C18: 62086 | D18: 117754 | E18: 172992 | H18: Доля в прибыли / убытке инвестиций, учитываемых методом долевого участия | I18: -6438 | J18: 5550 | K18: 21112 | L18: 17952
A19: Отложенный налоговый актив | B19: - | C19: 74 | D19: 30212 | E19: 41004 | H19: ОПЕРАЦИОННАЯ ПРИБЫЛЬ / УБЫТОК | I19: -12062 | J19: 124986 | K19: 360269 | L19: 426564
A20: ИТОГО ВНЕОБОРОТНЫЕ АКТИВЫ | B20: 1580048 | C20: 1598326 | D20: 2463916 | E20: 3058062
H21: Финансовые доходы | I21: 5328 | J21: 7474 | K21: 55601 | L21: 101082
A22: ОБОРОТНЫЕ АКТИВЫ | H22: Финансовые расходы | I22: -61790 | J22: -56758 | K22: -84721 | L22: -155856
A23: Денежные средства и денежные эквиваленты | B23: 134014 | C23: 198098 | D23: 62153 | E23: 277542 | H23: Денежная прибыль | I23: - | J23: - | K23: 182 | L23: 204
A24: Финансовые вложения | B24: 1332 | C24: 370 | D24: 486304 | E24: 341292 | H24: ПРИБЫЛЬ / УБЫТОК ДО НАЛОГООБЛОЖЕНИЯ | I24: -68524 | J24: 75702 | K24: 331331 | L24: 371994
A25: Дебиторская задолженность
A26: Аффилированные лица | B26: 1332 | C26: 1776 | D26: 4550 | E26: 4386 | H26: Налоговые доходы / расходы | I26: 6660 | J26: -4736 | K26: 216580 | L26: -22644
A27: Третьи стороны | B27: 45806 | C27: 66674 | D27: 73346 | E27: 87924 | H27: Текущий налог на прибыль | I27: - | J27: -2072 | K27: -6006 | L27: -39474
A28: Прочая дебиторская задолженность | H28: Отложенный налоговый доход / расход | I28: 6660 | J28: -2664 | K28: 222586 | L28: 16830
A29: Аффилированные лица | B29: 444 | C29: 444 | D29: 819 | E29: 918 | H29: Отложенный налоговый расход | I29: - | J29: -2664 | K29: -54327 | L29: -
A30: Третьи стороны | B30: 81030 | C30: 58534 | D30: 80080 | E30: 138618 | H30: Влияние корректировки на инфляцию на отложенный налоговый доход | I30: - | J30: - | K30: 276913 | L30: -
A31: Производные финансовые инструменты | B31: 148 | C31: 4366 | D31: 1638 | E31: 12138 | H31: ЧИСТАЯ ПРИБЫЛЬ / УБЫТОК ЗА ГОД | I31: -61864 | J31: 70966 | K31: 547911 | L31: 349350
A32: Запасы | B32: 22570 | C32: 19314 | D32: 38038 | E32: 68442
A33: Предоплаченные расходы | B33: 10434 | C33: 8436 | D33: 21567 | E33: 30804
A34: Текущий налог на прибыль | B34: 2812 | C34: 1480 | D34: 3731 | E34: 2958 | H34: ПРОЧИЙ СОВОКУПНЫЙ ДОХОД
A35: Прочие оборотные активы | B35: 9250 | C35: 5920 | D35: 9919 | E35: 23664
A36: ИТОГО ОБОРОТНЫЕ АКТИВЫ | B36: 309172 | C36: 365412 | D36: 782145 | E36: 988686 | H36: Статьи, которые могут быть впоследствии переклассифицированы в прибыль или убыток | I36: -46990 | J36: 38332 | K36: -11466 | L36: 34986
H37: Курсовые разницы | I37: -1258 | J37: -5476 | K37: 6643 | L37: 714
A38: ИТОГО АКТИВЫ | B38: 1889220 | C38: 1963738 | D38: 3246061 | E38: 4046748 | H38: Убытки от переоценки FVOCI | I38: 296 | J38: -814 | K38: 3185 | L38: -306
H39: Прибыль / убыток от переоценки хеджинговых инструментов, используемых для хеджирования денежных потоков | I39: -56684 | J39: 54612 | K39: -25298 | L39: 42942
H40: Прибыль / убыток от переоценки хеджинговых инструментов инвестиций, учитываемых методом долевого участия, используемых для хеджирования денежных потоков | I40: -814 | J40: 962 | K40: -819 | L40: 1530
A41: ОБЯЗАТЕЛЬСТВА И КАПИТАЛ | H41: Налог, относящийся к прочему совокупному доходу | I41: 11470 | J41: -10952 | K41: 4823 | L41: -9894
...

Sheet Ютэер
A1: Отчет о финансовом положении | I1: Отчет о прибылях и убытках
A2: на 31 декабря 202X года в миллионах рублей | I2: на 31 декабря 202X года в миллионах рублей
B3: 2020 г. | C3: 2021 г. | D3: 2023 г. | E3: 2024г. | J3: 2020 г. | K3: 2021 г. | L3: 2023 г. | M3: 2024 г.
A4: АКТИВЫ | I4: Выручка от пассажирских перевозок и вертолетных работ | J4: 55199 | K4: 75544 | L4: 97671 | M4: 111449
A5: Внеоборотные активы | I5: Выручка от прочей реализации | J5: 838 | K5: 1207 | L5: 1984 | M5: 1895
A6: Основные средства | B6: 26627 | C6: 30187 | D6: 58662 | E6: 62334 | I6: Выручка | J6: 56037 | K6: 76752 | L6: 99655 | M6: 113344
A7: Активы в форме права пользования | B7: 33577 | C7: 36306 | D7: 24210 | E7: 25161 | I7: Операционные расходы и доходы
A8: Нематериальные активы | B8: 56 | C8: 83 | D8: 40 | E8: 35 | I8: Прямые операционные расходы | J8: -25772 | K8: -37717 | L8: -52464 | M8: -60911
A9: Авансы под поставку основных средств и активов в форме права пользования | B9: 1391 | C9: 1474 | D9: 2442 | E9: 1401 | I9: Расходы на персонал | J9: -14920 | K9: -16821 | L9: -20176 | M9: -23060
A10: Долгосрочные финансовые активы | B10: 160 | C10: 2755 | D10: 8562 | E10: 9874 | I10: Износ и амортизация основных средств и активов в форме права пользования | J10: -8384 | K10: -7545 | L10: -14509 | M10: -18201
A11: Инвестиции в компании, учитываемые методом долевого участия | B11: 486 | C11: 404 | D11: 792 | E11: 82 | I11: Затраты на ремонт | J11: -2954 | K11: -4112 | L11: -2618 | M11: -2654
A12: Финансовые активы, оцениваемые по справедливой стоимости через прибыль или убыток | B12: 4 | C12: - | D12: - | E12: - | I12: Комиссионные вознаграждения | J12: -916 | K12: -1118 | L12: -936 | M12: -867
A13: Торговая и прочая дебиторская задолженность | B13: 764 | C13: 69 | D13: 393 | E13: 521 | I13: Государственные субсидии | J13: 3848 | K13: 2638 | L13: 3796 | M13: 3390
A14: Обеспечительные депозиты по аренде воздушных судов | B14: 280 | C14: 333 | D14: - | E14: - | I14: Операции по продаже и обратной аренде | J14: 134 | K14: 129 | L14: 4 | M14: 4
A15: Авансы выданные | B15: 7 | C15: 6 | D15: 53 | E15: 427 | I15: Прочие доходы | J15: 190 | K15: 578 | L15: 229 | M15: 181
A16: Итого внеоборотные активы | B16: 63350 | C16: 71618 | D16: 95156 | E16: 99834 | I16: Прочие расходы | J16: -3018 | K16: -3209 | L16: -2863 | M16: -2879
J17: -51791 | K17: -67177 | L17: -89537 | M17: -104996
I18: Результаты операционной деятельности | J18: 4245 | K18: 9575 | L18: 10118 | M18: 8348
A19: Оборотные активы
A20: Запасы | B20: 2122 | C20: 3436 | D20: 5666 | E20: 10221 | I20: Нетто-величина прибыли от изменения обменных курсов иностранных валют | J20: -2106 | K20: -8 | L20: -956 | M20: -2639
A21: Торговая и прочая дебиторская задолженность | B21: 3675 | C21: 5498 | D21: 6694 | E21: 6956 | I21: Резерв под ожидаемые кредитные убытки | J21: -656 | K21: -217 | L21: -1234 | M21: -486
A22: Затраты по договору | B22: 30 | C22: 92 | D22: 106 | E22: 139 | I22: Обесценивание авансов выданных | J22: - | K22: - | L22: -225 | M22: -839
A23: Авансы выданные | B23: 1058 | C23: 1761 | D23: 4892 | E23: 4376 | I23: Доля в прибыли (убытке) ассоциированных компаний | J23: -9 | K23: 231 | L23: 307 | M23: 316
A24: Налоги к возмещению | B24: 1865 | C24: 3585 | D24: 3643 | E24: 2970 | I24: Восстановление (списание) запасов до возможной стоимости реализации | J24: -222 | K24: 1195 | L24: 314 | M24: 11
A25: Дебиторская задолженность по налогу на прибыль | B25: 82 | C25: 353 | D25: 39 | E25: 23 | I25: Прибыль (убыток) от выбытия основных средств | J25: -142 | K25: 158 | L25: -210 | M25: -277
A26: Обеспечительные депозиты по аренде воздушных судов | B26: - | C26: 83 | D26: - | E26: - | I26: Убыток от обесценивания внеоборотных активов | J26: - | K26: - | L26: - | M26: -3171
A27: Краткосрочные финансовые активы | B27: 1245 | C27: 1463 | D27: 1429 | E27: 170 | I27: Результат от переоценки и обесценения активов | J27: -5902 | K27: -10 | L27: - | M27: -
A28: Денежные средства и их эквиваленты | B28: 12679 | C28: 7569 | D28: 5537 | E28: 5337 | I28: (Убыток) прибыль от расторжения договоров аренды | J28: 100 | K28: -83412 | L28: 124 | M28: -2
A29: Итого оборотные активы | B29: 22756 | C29: 23840 | D29: 28007 | E29: 30191 | I29: Прибыль от реструктуризации финансовых обязательств | J29: 14399 | K29: 28531 | L29: - | M29: -
A30: Активы, удерживаемые для продажи | B30: - | C30: - | D30: - | E30: 324 | I30: Финансовые доходы | J30: 695 | K30: 442 | L30: 1294 | M30: 1231
I31: Финансовые расходы | J31: -6673 | K31: -5865 | L31: -5936 | M31: -7553
A32: Всего активы | B32: 86106 | C32: 95458 | D32: 123163 | E32: 130350 | I32: Прибыль до налогообложения | J32: 3671 | K32: 33950 | L32: 3596 | M32: -5062
A33: Собственный капитал | I33: Расход по налогу на прибыль | J33: -542 | K33: -7125 | L33: -809 | M33: -1954
A34: Акционерный капитал | B34: 3702 | C34: 7896 | D34: 7896 | E34: 7896 | I34: Прибыль (убыток) за год | J34: 3130 | K34: 26825 | L34: 2786 | M34: -7015
A35: Эмиссионный доход | B35: 21875 | C35: 31311 | D35: 31311 | E35: 31311
A36: Собственные выкупленные акции | B36: -1352 | C36: -7402 | D36: -7402 | E36: -7402
A37: Резерв курсовых разниц при пересчете из других валют | B37: 334 | C37: 417 | D37: -825 | E37: -1431 | I37: ИСТОЧНИКИ
A38: Резерв на переоценку основных средств и активов в форме права пользования | B38: 17849 | C38: 17912 | D38: 21779 | E38: 20492 | I38: Очет о прибылях и убытках - | J38: https://smart-lab.ru/q/UTAR/f/y/MSFO/
A39: Результат оценки актуарных обязательств | B39: -31 | C39: -63 | D39: 91 | E39: 121 | I39: Отчет о финансовом положении - | J39: https://smart-lab.ru/q/UTAR/f/y/MSFO/
A40: Непокрытый убыток | B40: -67980 | C40: -39918 | D40: -30499 | E40: -37135
...

Sheet Метрики
A1: Метрики
B2: 2020 г. | C2: 2021 г. | D2: 2023 г. | E2: 2024 г. | F2: 2020 г. | G2: 2021 г. | H2: 2023 г. | I2: 2024 г. | J2: 2020 г. | K2: 2021 г. | L2: 2023 г. | M2: 2024 г.
B3: Аэрофлот | F3: Utair | J3: TurkishAirlines
A4: Ликвидность
A5: Текущая | B5: ='Аэрофлот'!B13/'Аэрофлот'!B41 -> 0.65798745 | C5: ='Аэрофлот'!C13/'Аэрофлот'!C41 -> 0.69828459 | D5: ='Аэрофлот'!D13/'Аэрофлот'!D41 -> 0.73851309 | E5: ='Аэрофлот'!E13/'Аэрофлот'!E41 -> 0.62028528 | F5: 0.3063131 | G5: 0.87889401 | H5: 0.76224043 | I5: 0.62607055 | J5: 0.64735048 | K5: 0.72907131 | L5: 0.94585672 | M5: 1.0090568
A6: Быстрая | B6: =('Аэрофлот'!B6+'Аэрофлот'!B7+'Аэрофлот'!B8)/'Аэрофлот'!B41 -> 0.57175463 | C6: =('Аэрофлот'!C6+'Аэрофлот'!C7+'Аэрофлот'!C8)/'Аэрофлот'!C41 -> 0.61252146 | D6: =('Аэрофлот'!D6+'Аэрофлот'!D7+'Аэрофлот'!D8)/'Аэрофлот'!D41 -> 0.58711912 | E6: =('Аэрофлот'!E6+'Аэрофлот'!E7+'Аэрофлот'!E8)/'Аэрофлот'!E41 -> 0.47152897 | F6: 0.20685928 | G6: 0.2172059 | H6: 0.18499241 | I6: 0.17140047 | J6: 0.60009297 | K6: 0.69053595 | L6: 0.89985694 | M6: 0.93920466
A7: Абсолютная | B7: =('Аэрофлот'!B6+'Аэрофлот'!B7)/'Аэрофлот'!B41 -> 0.33338073 | C7: =('Аэрофлот'!C6+'Аэрофлот'!C7)/'Аэрофлот'!C41 -> 0.34393664 | D7: =('Аэрофлот'!D6+'Аэрофлот'!D7)/'Аэрофлот'!D41 -> 0.34488993 | E7: =('Аэрофлот'!E6+'Аэрофлот'!E7)/'Аэрофлот'!E41 -> 0.25774877 | F7: 0.170669 | G7: 0.27904147 | H7: 0.15069537 | I7: 0.11067333 | J7: 0.28339015 | K7: 0.39598405 | L7: 0.6632552 | M7: 0.63158443
A9: Финансовая устойчивость
A10: Коэффициент автономии | B10: =abs('Аэрофлот'!B65)/(abs('Аэрофлот'!B65)+'Аэрофлот'!B52) -> 0.092506512 | C10: =abs('Аэрофлот'!C65)/(abs('Аэрофлот'!C65)+'Аэрофлот'!C52) -> 0.10442508 | D10: =abs('Аэрофлот'!D65)/(abs('Аэрофлот'!D65)+'Аэрофлот'!D52) -> 0.07529725 | E10: =abs('Аэрофлот'!E65)/(abs('Аэрофлот'!E65)+'Аэрофлот'!E52) -> 0.055685964 | F10: 0.042472641 | G10: 0.11314924 | H10: 0.18728839 | I10: 0.11081788 | J10: 0.21084998 | K10: 0.25764028 | L10: 0.43629279 | M10: 0.48681756
A11: Коэффициент соотношения заемных и собственных средств | B11: =('Аэрофлот'!B41+'Аэрофлот'!B50)/'Аэрофлот'!B65 -> -9.8100498 | C11: =('Аэрофлот'!C41+'Аэрофлот'!C50)/'Аэрофлот'!C65 -> -8.5762439 | D11: =('Аэрофлот'!D41+'Аэрофлот'!D50)/'Аэрофлот'!D65 -> -12.280697 | E11: =('Аэрофлот'!E41+'Аэрофлот'!E50)/'Аэрофлот'!E65 -> -16.957847 | F11: -22.544569 | G11: 7.8378854 | H11: 4.3393593 | I11: 8.0238145 | J11: 3.7427085 | K11: 2.8813807 | L11: 1.2920388 | M11: 1.0541576
A12: Коэффициент финансового левериджа | B12: ='Аэрофлот'!B28/'Аэрофлот'!B65 -> -8.8100498 | C12: ='Аэрофлот'!C28/'Аэрофлот'!C65 -> -7.5762439 | D12: ='Аэрофлот'!D28/'Аэрофлот'!D65 -> -11.280697 | E12: ='Аэрофлот'!E28/'Аэрофлот'!E65 -> -15.957847 | F12: -17.483452 | G12: 8.8378854 | H12: 5.3393593 | I12: 9.0238837 | J12: 4.7427085 | K12: 3.8813807 | L12: 2.2920388 | M12: 2.0541576
A14: Коэффициенты деловой активности
A15: Оборачиваемость активов | B15: =('Аэрофлот'!J6)/(('Аэрофлот'!B119+'Аэрофлот'!B28)/2) -> 0.31000625 | C15: =('Аэрофлот'!K6)/(('Аэрофлот'!C119+'Аэрофлот'!C28)/2) -> 0.88644463 | D15: =('Аэрофлот'!L6)/(('Аэрофлот'!D119+'Аэрофлот'!D28)/2) -> 1.0990777 | E15: =('Аэрофлот'!M6)/(('Аэрофлот'!E119+'Аэрофлот'!E28)/2) -> 1.4811789 | F15: 1.0853048 | G15: 0.84545394 | H15: 0.91166905 | I15: 0.89418689 | J15: - | K15: 0.41047112 | L15: 0.73159137 | M15: 0.63411451
A16: Оборачиваемость дебиторской задолженности (в днях) | B16: =(('Аэрофлот'!B120+'Аэрофлот'!B8)/2)*365/('Аэрофлот'!J6) -> 98.755171 | C16: =(('Аэрофлот'!B8+'Аэрофлот'!C8)*365/2)/('Аэрофлот'!K6) -> 52.057072 | D16: =(('Аэрофлот'!C8+'Аэрофлот'!D8)/2)*365/('Аэрофлот'!L6) -> 46.348359 | E16: =(('Аэрофлот'!D8+'Аэрофлот'!E8)/2)*365/('Аэрофлот'!M6) -> 36.149606 | F16: 37.873057 | G16: 22.845789 | H16: 23.045306 | I16: 22.078275 | J16: - | K16: 94.375351 | L16: 45.70367 | M16: 51.027967
A18: Коэффициенты рентабельности
A19: Рентабельность продаж (ROS) % | B19: ='Аэрофлот'!J24*100/'Аэрофлот'!J6 -> -40.772779 | C19: ='Аэрофлот'!K24*100/'Аэрофлот'!K6 -> -7.0078681 | D19: ='Аэрофлот'!L24*100/'Аэрофлот'!L6 -> -2.2902871 | E19: ='Аэрофлот'!M24*100/'Аэрофлот'!M6 -> 6.4216811 | F19: 5.5855952 | G19: 34.950229 | H19: 2.795645 | I19: -6.1891234 | J19: -12.414612 | K19: 8.974359 | L19: 28.750836 | M19: 15.108739
A20: Рентабельность активов (ROA) % | B20: ='Аэрофлот'!J24*100/(('Аэрофлот'!B119+'Аэрофлот'!B28)/2) -> -12.639816 | C20: ='Аэрофлот'!K24*100/(('Аэрофлот'!B28+'Аэрофлот'!C28)/2) -> -3.2422963 | D20: ='Аэрофлот'!L24*100/(('Аэрофлот'!C28+'Аэрофлот'!D28)/2) -> -1.2611853 | E20: ='Аэрофлот'!M24*100/(('Аэрофлот'!D28+'Аэрофлот'!E28)/2) -> 4.8456346 | F20: 6.0620733 | G20: 29.548809 | H20: 2.548703 | I20: -5.534233 | J20: - | K20: 3.6837152 | L20: 21.033863 | M20: 9.5806705
A21: Рентабельность собственного капитала (ROE) % | B21: - | C21: =('Аэрофлот'!K24)*100/(('Аэрофлот'!B65+'Аэрофлот'!C65)/2) -> 26.327048 | D21: =('Аэрофлот'!L24)*100/(('Аэрофлот'!C65+'Аэрофлот'!D65)/2) -> 11.436752 | E21: =('Аэрофлот'!M24)*100/(('Аэрофлот'!D65+'Аэрофлот'!E65)/2) -> -64.256559 | F21: 19.930593 | G21: 913.03608 | H21: 16.452108 | I21: -37.401365 | J21: - | K21: 15.695581 | L21: 57.0096 | M21: 20.633377

Sheet Горизонтальный анализ
A1: Горизонтальный анализ (Аэрофлот) ОФП | F1: Изменения (базовый год 2020)
F2: Абсолютные отклонения | G2: Относительные отклонения | I2: Абсолютные отклонения | J2: Относительные отклонения | L2: Абсолютные отклонения | M2: Относительные отклонения
A3: на 31 декабря 202X года в миллионах рублей, если не указано иное | G3: Темп роста | H3: Темп прироста | J3: Темп роста | K3: Темп прироста | M3: Темп роста | N3: Темп прироста
B4: 2020 г. | C4: 2021 г. | D4: 2023 г. | E4: 2024 г. | F4: 2021 г. | I4: 2023 г. | L4: 2024 г. | O4: Абсолютные отклонения | P4: Темпы роста | Q4: Темпы прироста
A5: АКТИВЫ
A6: Оборотные активы
A7: Денежные средства и их эквиваленты | B7: 88944 | C7: 74180 | D7: 83117 | E7: 67814 | F7: =(C7-B7) -> -14764 | G7: =(C7/B7) -> 0.83400792 | H7: =(C7-B7)/B7 -> -0.16599208 | I7: =(D7-B7) -> -5827 | J7: =(D7/B7) -> 0.93448687 | K7: =(D7-B7)/B7 -> -0.065513132 | L7: =(E7-B7) -> -21130 | M7: =(E7/B7) -> 0.76243479 | N7: =(E7-B7)/B7 -> -0.23756521 | O7: =IFERROR(__xludf.DUMMYFUNCTION("SPARKLINE({F7; I7; L7},{""charttype"",""line"";""color"",""green""}) "),"") | P7: =IFERROR(__xludf.DUMMYFUNCTION("SPARKLINE({G7; J7; M7},{""charttype"",""column"";""color"",""green""})"),"") | Q7: =IFERROR(__xludf.DUMMYFUNCTION("SPARKLINE({H7;K7;N7},{""charttype"",""line"";""color"",""black""})"),"")
A8: Дебиторская задолженность и предоплаты | B8: 67051 | C8: 73213 | D8: 82262 | E8: 87450 | F8: =(C8-B8) -> 6162 | G8: =(C8/B8) -> 1.0919002 | H8: =(C8-B8)/B8 -> 0.091900195 | I8: =(D8-B8) -> 15211 | J8: =(D8/B8) -> 1.2268572 | K8: =(D8-B8)/B8 -> 0.22685717 | L8: =(E8-B8) -> 20399 | M8: =(E8/B8) -> 1.3042311 | N8: =(E8-B8)/B8 -> 0.30423111 | O8: =IFERROR(__xludf.DUMMYFUNCTION("SPARKLINE({F8; I8; L8},{""charttype"",""line"";""color"",""green""}) "),"") | P8: =IFERROR(__xludf.DUMMYFUNCTION("SPARKLINE({G8; J8; M8},{""charttype"",""column"";""color"",""green""})"),"") | Q8: =IFERROR(__xludf.DUMMYFUNCTION("SPARKLINE({H8;K8;N8},{""charttype"",""line"";""color"",""black""})"),"")
A9: Итого оборотные активы | B9: 185082 | C9: 190344 | D9: 250802 | E9: 253737 | F9: =(C9-B9) -> 5262 | G9: =(C9/B9) -> 1.0284306 | H9: =(C9-B9)/B9 -> 0.028430642 | I9: =(D9-B9) -> 65720 | J9: =(D9/B9) -> 1.3550859 | K9: =(D9-B9)/B9 -> 0.35508585 | L9: =(E9-B9) -> 68655 | M9: =(E9/B9) -> 1.3709437 | N9: =(E9-B9)/B9 -> 0.37094369 | O9: =IFERROR(__xludf.DUMMYFUNCTION("SPARKLINE({F9; I9; L9},{""charttype"",""line"";""color"",""green""}) "),"") | P9: =IFERROR(__xludf.DUMMYFUNCTION("SPARKLINE({G9; J9; M9},{""charttype"",""column"";""color"",""green""})"),"") | Q9: =IFERROR(__xludf.DUMMYFUNCTION("SPARKLINE({H9;K9;N9},{""charttype"",""line"";""color"",""black""})"),"")
A10: Внеоборотные активы
A11: Активы в форме права пользования | B11: 635406 | C11: 725421 | D11: 619883 | E11: 557557 | F11: =(C11-B11) -> 90015 | G11: =(C11/B11) -> 1.1416653 | H11: =(C11-B11)/B11 -> 0.14166533 | I11: =(D11-B11) -> -15523 | J11: =(D11/B11) -> 0.97556995 | K11: =(D11-B11)/B11 -> -0.024430049 | L11: =(E11-B11) -> -77849 | M11: =(E11/B11) -> 0.87748148 | N11: =(E11-B11)/B11 -> -0.12251852 | O11: =IFERROR(__xludf.DUMMYFUNCTION("SPARKLINE({F11; I11; L11},{""charttype"",""line"";""color"",""green""}) "),"") | P11: =IFERROR(__xludf.DUMMYFUNCTION("SPARKLINE({G11; J11; M11},{""charttype"",""column"";""color"",""green""})"),"") | Q11: =IFERROR(__xludf.DUMMYFUNCTION("SPARKLINE({H11;K11;N11},{""charttype"",""line"";""color"",""black""})"),"")
A12: Основные средства | B12: 19825 | C12: 19893 | D12: 104922 | E12: 159838 | F12: =(C12-B12) -> 68 | G12: =(C12/B12) -> 1.00343 | H12: =(C12-B12)/B12 -> 0.0034300126 | I12: =(D12-B12) -> 85097 | J12: =(D12/B12) -> 5.2924086 | K12: =(D12-B12)/B12 -> 4.2924086 | L12: =(E12-B12) -> 140013 | M12: =(E12/B12) -> 8.0624464 | N12: =(E12-B12)/B12 -> 7.0624464 | O12: =IFERROR(__xludf.DUMMYFUNCTION("SPARKLINE({F12; I12; L12},{""charttype"",""line"";""color"",""green""}) "),"") | P12: =IFERROR(__xludf.DUMMYFUNCTION("SPARKLINE({G12; J12; M12},{""charttype"",""column"";""color"",""green""})"),"") | Q12: =IFERROR(__xludf.DUMMYFUNCTION("SPARKLINE({H12;K12;N12},{""charttype"",""line"";""color"",""black""})"),"")
A13: Долгосрочные финансовые инвестиции | B13: 5464 | C13: 5360 | D13: 5335 | E13: 6123 | F13: =(C13-B13) -> -104 | G13: =(C13/B13) -> 0.98096633 | H13: =(C13-B13)/B13 -> -0.019033675 | I13: =(D13-B13) -> -129 | J13: =(D13/B13) -> 0.97639092 | K13: =(D13-B13)/B13 -> -0.023609078 | L13: =(E13-B13) -> 659 | M13: =(E13/B13) -> 1.1206076 | N13: =(E13-B13)/B13 -> 0.12060761 | O13: =IFERROR(__xludf.DUMMYFUNCTION("SPARKLINE({F13; I13; L13},{""charttype"",""line"";""color"",""green""}) "),"") | P13: =IFERROR(__xludf.DUMMYFUNCTION("SPARKLINE({G13; J13; M13},{""charttype"",""column"";""color"",""green""})"),"") | Q13: =IFERROR(__xludf.DUMMYFUNCTION("SPARKLINE({H13;K13;N13},{""charttype"",""line"";""color"",""black""})"),"")
A14: Нематериальные активы | B14: 2414 | C14: 3221 | D14: 7475 | E14: 21245 | F14: =(C14-B14) -> 807 | G14: =(C14/B14) -> 1.3342999 | H14: =(C14-B14)/B14 -> 0.33429992 | I14: =(D14-B14) -> 5061 | J14: =(D14/B14) -> 3.0965203 | K14: =(D14-B14)/B14 -> 2.0965203 | L14: =(E14-B14) -> 18831 | M14: =(E14/B14) -> 8.8007456 | N14: =(E14-B14)/B14 -> 7.8007456 | O14: =IFERROR(__xludf.DUMMYFUNCTION("SPARKLINE({F14; I14; L14},{""charttype"",""line"";""color"",""green""}) "),"") | P14: =IFERROR(__xludf.DUMMYFUNCTION("SPARKLINE({G14; J14; M14},{""charttype"",""column"";""color"",""green""})"),"") | Q14: =IFERROR(__xludf.DUMMYFUNCTION("SPARKLINE({H14;K14;N14},{""charttype"",""line"";""color"",""black""})"),"")
A15: Инвестиции в ассоциированные компании | B15: 419 | C15: 538 | D15: 518 | E15: 1541 | F15: =(C15-B15) -> 119 | G15: =(C15/B15) -> 1.2840095 | H15: =(C15-B15)/B15 -> 0.28400955 | I15: =(D15-B15) -> 99 | J15: =(D15/B15) -> 1.2362769 | K15: =(D15-B15)/B15 -> 0.23627685 | L15: =(E15-B15) -> 1122 | M15: =(E15/B15) -> 3.6778043 | N15: =(E15-B15)/B15 -> 2.6778043 | O15: =IFERROR(__xludf.DUMMYFUNCTION("SPARKLINE({F15; I15; L15},{""charttype"",""line"";""color"",""green""}) "),"") | P15: =IFERROR(__xludf.DUMMYFUNCTION("SPARKLINE({G15; J15; M15},{""charttype"",""column"";""color"",""green""})"),"") | Q15: =IFERROR(__xludf.DUMMYFUNCTION("SPARKLINE({H15;K15;N15},{""charttype"",""line"";""color"",""black""})"),"")
A16: Итого внеоборотные активы | B16: 831122 | C16: 919106 | D16: 863212 | E16: 903159 | F16: =(C16-B16) -> 87984 | G16: =(C16/B16) -> 1.1058617 | H16: =(C16-B16)/B16 -> 0.10586171 | I16: =(D16-B16) -> 32090 | J16: =(D16/B16) -> 1.0386105 | K16: =(D16-B16)/B16 -> 0.038610457 | L16: =(E16-B16) -> 72037 | M16: =(E16/B16) -> 1.0866744 | N16: =(E16-B16)/B16 -> 0.086674399 | O16: =IFERROR(__xludf.DUMMYFUNCTION("SPARKLINE({F16; I16; L16},{""charttype"",""line"";""color"",""green""}) "),"") | P16: =IFERROR(__xludf.DUMMYFUNCTION("SPARKLINE({G16; J16; M16},{""charttype"",""column"";""color"",""green""})"),"") | Q16: =IFERROR(__xludf.DUMMYFUNCTION("SPARKLINE({H16;K16;N16},{""charttype"",""line"";""color"",""black""})"),"")
A17: ИТОГО АКТИВЫ | B17: 1016204 | C17: 1109450 | D17: 1114014 | E17: 1156896 | F17: =(C17-B17) -> 93246 | G17: =(C17/B17) -> 1.0917591 | H17: =(C17-B17)/B17 -> 0.091759135 | I17: =(D17-B17) -> 97810 | J17: =(D17/B17) -> 1.0962504 | K17: =(D17-B17)/B17 -> 0.096250359 | L17: =(E17-B17) -> 140692 | M17: =(E17/B17) -> 1.1384486 | N17: =(E17-B17)/B17 -> 0.13844858 | O17: =IFERROR(__xludf.DUMMYFUNCTION("SPARKLINE({F17; I17; L17},{""charttype"",""line"";""color"",""green""}) "),"") | P17: =IFERROR(__xludf.DUMMYFUNCTION("SPARKLINE({G17; J17; M17},{""charttype"",""column"";""color"",""green""})"),"") | Q17: =IFERROR(__xludf.DUMMYFUNCTION("SPARKLINE({H17;K17;N17},{""charttype"",""line"";""color"",""black""})"),"")
A18: ОБЯЗАТЕЛЬСТВА И КАПИТАЛ
A19: Краткосрочные обязательства
A20: Краткосрочные кредиты и займы и краткосрочная часть долгосрочных кредитов и займов | B20: 34924 | C20: 17500 | D20: 44178 | E20: 19746 | F20: =(C20-B20) -> -17424 | G20: =(C20/B20) -> 0.50108808 | H20: =(C20-B20)/B20 -> -0.49891192 | I20: =(D20-B20) -> 9254 | J20: =(D20/B20) -> 1.2649754 | K20: =(D20-B20)/B20 -> 0.26497538 | L20: =(E20-B20) -> -15178 | M20: =(E20/B20) -> 0.56539915 | N20: =(E20-B20)/B20 -> -0.43460085 | O20: =IFERROR(__xludf.DUMMYFUNCTION("SPARKLINE({F20; I20; L20},{""charttype"",""line"";""color"",""green""}) "),"") | P20: =IFERROR(__xludf.DUMMYFUNCTION("SPARKLINE({G20; J20; M20},{""charttype"",""column"";""color"",""green""})"),"") | Q20: =IFERROR(__xludf.DUMMYFUNCTION("SPARKLINE({H20;K20;N20},{""charttype"",""line"";""color"",""black""})"),"")
A21: Обязательства по текущему налогу на прибыль | B21: 4 | C21: 141 | D21: 905 | E21: 754 | F21: =(C21-B21) -> 137 | G21: =(C21/B21) -> 35.25 | H21: =(C21-B21)/B21 -> 34.25 | I21: =(D21-B21) -> 901 | J21: =(D21/B21) -> 226.25 | K21: =(D21-B21)/B21 -> 225.25 | L21: =(E21-B21) -> 750 | M21: =(E21/B21) -> 188.5 | N21: =(E21-B21)/B21 -> 187.5 | O21: =IFERROR(__xludf.DUMMYFUNCTION("SPARKLINE({F21; I21; L21},{""charttype"",""line"";""color"",""green""}) "),"") | P21: =IFERROR(__xludf.DUMMYFUNCTION("SPARKLINE({G21; J21; M21},{""charttype"",""column"";""color"",""green""})"),"") | Q21: =IFERROR(__xludf.DUMMYFUNCTION("SPARKLINE({H21;K21;N21},{""charttype"",""line"";""color"",""black""})"),"")
A22: Итого краткосрочные обязательства | B22: 281285 | C22: 272588 | D22: 339604 | E22: 409065 | F22: =(C22-B22) -> -8697 | G22: =(C22/B22) -> 0.96908118 | H22: =(C22-B22)/B22 -> -0.030918819 | I22: =(D22-B22) -> 58319 | J22: =(D22/B22) -> 1.2073306 | K22: =(D22-B22)/B22 -> 0.20733064 | L22: =(E22-B22) -> 127780 | M22: =(E22/B22) -> 1.4542724 | N22: =(E22-B22)/B22 -> 0.45427236 | O22: =IFERROR(__xludf.DUMMYFUNCTION("SPARKLINE({F22; I22; L22},{""charttype"",""line"";""color"",""green""}) "),"") | P22: =IFERROR(__xludf.DUMMYFUNCTION("SPARKLINE({G22; J22; M22},{""charttype"",""column"";""color"",""green""})"),"") | Q22: =IFERROR(__xludf.DUMMYFUNCTION("SPARKLINE({H22;K22;N22},{""charttype"",""line"";""color"",""black""})"),"")
A23: Долгосрочные обязательства
A24: Долгосрочные кредиты и займы | B24: 53711 | C24: 114768 | D24: 60190 | E24: 40722 | F24: =(C24-B24) -> 61057 | G24: =(C24/B24) -> 2.136769 | H24: =(C24-B24)/B24 -> 1.136769 | I24: =(D24-B24) -> 6479 | J24: =(D24/B24) -> 1.1206271 | K24: =(D24-B24)/B24 -> 0.12062706 | L24: =(E24-B24) -> -12989 | M24: =(E24/B24) -> 0.75816872 | N24: =(E24-B24)/B24 -> -0.24183128 | O24: =IFERROR(__xludf.DUMMYFUNCTION("SPARKLINE({F24; I24; L24},{""charttype"",""line"";""color"",""green""}) "),"") | P24: =IFERROR(__xludf.DUMMYFUNCTION("SPARKLINE({G24; J24; M24},{""charttype"",""column"";""color"",""green""})"),"") | Q24: =IFERROR(__xludf.DUMMYFUNCTION("SPARKLINE({H24;K24;N24},{""charttype"",""line"";""color"",""black""})"),"")
A25: Прочие долгосрочные обязательства | B25: 20666 | C25: 15552 | D25: 9913 | E25: 4982 | F25: =(C25-B25) -> -5114 | G25: =(C25/B25) -> 0.7525404 | H25: =(C25-B25)/B25 -> -0.2474596 | I25: =(D25-B25) -> -10753 | J25: =(D25/B25) -> 0.47967676 | K25: =(D25-B25)/B25 -> -0.52032324 | L25: =(E25-B25) -> -15684 | M25: =(E25/B25) -> 0.24107229 | N25: =(E25-B25)/B25 -> -0.75892771 | O25: =IFERROR(__xludf.DUMMYFUNCTION("SPARKLINE({F25; I25; L25},{""charttype"",""line"";""color"",""green""}) "),"") | P25: =IFERROR(__xludf.DUMMYFUNCTION("SPARKLINE({G25; J25; M25},{""charttype"",""column"";""color"",""green""})"),"") | Q25: =IFERROR(__xludf.DUMMYFUNCTION("SPARKLINE({H25;K25;N25},{""charttype"",""line"";""color"",""black""})"),"") | U25: Темпы роста капитала Аэрофлота относительно базового года
A26: Итого долгосрочные обязательства | B26: 850265 | C26: 983300 | D26: 873164 | E26: 820328 | F26: =(C26-B26) -> 133035 | G26: =(C26/B26) -> 1.156463 | H26: =(C26-B26)/B26 -> 0.15646299 | I26: =(D26-B26) -> 22899 | J26: =(D26/B26) -> 1.0269316 | K26: =(D26-B26)/B26 -> 0.026931604 | L26: =(E26-B26) -> -29937 | M26: =(E26/B26) -> 0.96479098 | N26: =(E26-B26)/B26 -> -0.035209023 | O26: =IFERROR(__xludf.DUMMYFUNCTION("SPARKLINE({F26; I26; L26},{""charttype"",""line"";""color"",""green""}) "),"") | P26: =IFERROR(__xludf.DUMMYFUNCTION("SPARKLINE({G26; J26; M26},{""charttype"",""column"";""color"",""green""})"),"") | Q26: =IFERROR(__xludf.DUMMYFUNCTION("SPARKLINE({H26;K26;N26},{""charttype"",""line"";""color"",""black""})"),"") | U26: год | V26: Уставный капитал | W26: Добавочный капитал | X26: Капитал, приходящийся на акционеров компании | Y26: Держатели неконтролирующих долей участия
A27: ИТОГО ОБЯЗАТЕЛЬСТВА | B27: 1131550 | C27: 1255888 | D27: 1212768 | E27: 1229393 | F27: =(C27-B27) -> 124338 | G27: =(C27/B27) -> 1.1098829 | H27: =(C27-B27)/B27 -> 0.1098829 | I27: =(D27-B27) -> 81218 | J27: =(D27/B27) -> 1.0717759 | K27: =(D27-B27)/B27 -> 0.071775883 | L27: =(E27-B27) -> 97843 | M27: =(E27/B27) -> 1.0864681 | N27: =(E27-B27)/B27 -> 0.086468119 | O27: =IFERROR(__xludf.DUMMYFUNCTION("SPARKLINE({F27; I27; L27},{""charttype"",""line"";""color"",""green""}) "),"") | P27: =IFERROR(__xludf.DUMMYFUNCTION("SPARKLINE({G27; J27; M27},{""charttype"",""column"";""color"",""green""})"),"") | Q27: =IFERROR(__xludf.DUMMYFUNCTION("SPARKLINE({H27;K27;N27},{""charttype"",""line"";""color"",""black""})"),"") | U27: 2021г | V27: =(C29/B29) -> 1 | W27: =(C30/B30) -> 1 | X27: =(C31/B31) -> 1.285082 | Y27: =(C32/B32) -> 1.0484808
A28: Капитал | U28: 2023г | V28: =(D29/B29) -> 1.568511 | W28: =(D30/B30) -> 1.8348179 | X28: =(D31/B31) -> 0.79371103 | Y28: =(D32/B32) -> 1.7451783
A29: Уставный капитал | B29: 2693 | C29: 2693 | D29: 4224 | E29: 4224 | F29: =(C29-B29) -> 0 | G29: =(C29/B29) -> 1 | H29: =(C29-B29)/B29 -> 0 | I29: =(D29-B29) -> 1531 | J29: =(D29/B29) -> 1.568511 | K29: =(D29-B29)/B29 -> 0.56851095 | L29: =(E29-B29) -> 1531 | M29: =(E29/B29) -> 1.568511 | N29: =(E29-B29)/B29 -> 0.56851095 | O29: =IFERROR(__xludf.DUMMYFUNCTION("SPARKLINE({F29; I29; L29},{""charttype"",""line"";""color"",""green""}) "),"") | P29: =IFERROR(__xludf.DUMMYFUNCTION("SPARKLINE({G29; J29; M29},{""charttype"",""column"";""color"",""green""})"),"") | Q29: =IFERROR(__xludf.DUMMYFUNCTION("SPARKLINE({H29;K29;N29},{""charttype"",""line"";""color"",""black""})"),"") | U29: 2024г | V29: =(E29/B29) -> 1.568511 | W29: =(E30/B30) -> 1.823128 | X29: =(E31/B31) -> 0.51692399 | Y29: =(E32/B32) -> 2.2173052
A30: Добавочный капитал | B30: 78701 | C30: 78701 | D30: 144402 | E30: 143482 | F30: =(C30-B30) -> 0 | G30: =(C30/B30) -> 1 | H30: =(C30-B30)/B30 -> 0 | I30: =(D30-B30) -> 65701 | J30: =(D30/B30) -> 1.8348179 | K30: =(D30-B30)/B30 -> 0.83481785 | L30: =(E30-B30) -> 64781 | M30: =(E30/B30) -> 1.823128 | N30: =(E30-B30)/B30 -> 0.82312804 | O30: =IFERROR(__xludf.DUMMYFUNCTION("SPARKLINE({F30; I30; L30},{""charttype"",""line"";""color"",""green""}) "),"") | P30: =IFERROR(__xludf.DUMMYFUNCTION("SPARKLINE({G30; J30; M30},{""charttype"",""column"";""color"",""green""})"),"") | Q30: =IFERROR(__xludf.DUMMYFUNCTION("SPARKLINE({H30;K30;N30},{""charttype"",""line"";""color"",""black""})"),"")
A31: Капитал, приходящийся на акционеров Компании | B31: -107776 | C31: -138501 | D31: -85543 | E31: -55712 | F31: =(C31-B31) -> -30725 | G31: =(C31/B31) -> 1.285082 | H31: =(C31-B31)/B31 -> 0.28508202 | I31: =(D31-B31) -> 22233 | J31: =(D31/B31) -> 0.79371103 | K31: =(D31-B31)/B31 -> -0.20628897 | L31: =(E31-B31) -> 52064 | M31: =(E31/B31) -> 0.51692399 | N31: =(E31-B31)/B31 -> -0.48307601 | O31: =IFERROR(__xludf.DUMMYFUNCTION("SPARKLINE({F31; I31; L31},{""charttype"",""line"";""color"",""green""}) "),"") | P31: =IFERROR(__xludf.DUMMYFUNCTION("SPARKLINE({G31; J31; M31},{""charttype"",""column"";""color"",""green""})"),"") | Q31: =IFERROR(__xludf.DUMMYFUNCTION("SPARKLINE({H31;K31;N31},{""charttype"",""line"";""color"",""black""})"),"")
A32: Держатели неконтролирующих долей участия | B32: -7570 | C32: -7937 | D32: -13211 | E32: -16785 | F32: =(C32-B32) -> -367 | G32: =(C32/B32) -> 1.0484808 | H32: =(C32-B32)/B32 -> 0.048480845 | I32: =(D32-B32) -> -5641 | J32: =(D32/B32) -> 1.7451783 | K32: =(D32-B32)/B32 -> 0.74517834 | L32: =(E32-B32) -> -9215 | M32: =(E32/B32) -> 2.2173052 | N32: =(E32-B32)/B32 -> 1.2173052 | O32: =IFERROR(__xludf.DUMMYFUNCTION("SPARKLINE({F32; I32; L32},{""charttype"",""line"";""color"",""green""}) "),"") | P32: =IFERROR(__xludf.DUMMYFUNCTION("SPARKLINE({G32; J32; M32},{""charttype"",""column"";""color"",""green""})"),"") | Q32: =IFERROR(__xludf.DUMMYFUNCTION("SPARKLINE({H32;K32;N32},{""charttype"",""line"";""color"",""black""})"),"")
A33: ИТОГО КАПИТАЛ | B33: -115346 | C33: -146438 | D33: -98754 | E33: -72497 | F33: =(C33-B33) -> -31092 | G33: =(C33/B33) -> 1.2695542 | H33: =(C33-B33)/B33 -> 0.26955421 | I33: =(D33-B33) -> 16592 | J33: =(D33/B33) -> 0.85615453 | K33: =(D33-B33)/B33 -> -0.14384547 | L33: =(E33-B33) -> 42849 | M33: =(E33/B33) -> 0.62851768 | N33: =(E33-B33)/B33 -> -0.37148232 | O33: =IFERROR(__xludf.DUMMYFUNCTION("SPARKLINE({F33; I33; L33},{""charttype"",""line"";""color"",""green""}) "),"") | P33: =IFERROR(__xludf.DUMMYFUNCTION("SPARKLINE({G33; J33; M33},{""charttype"",""column"";""color"",""green""})"),"") | Q33: =IFERROR(__xludf.DUMMYFUNCTION("SPARKLINE({H33;K33;N33},{""charttype"",""line"";""color"",""black""})"),"")
A34: ИТОГО ОБЯЗАТЕЛЬСТВА И КАПИТАЛ | B34: 1016204 | C34: 1109450 | D34: 1114014 | E34: 1156896 | F34: =(C34-B34) -> 93246 | G34: =(C34/B34) -> 1.0917591 | H34: =(C34-B34)/B34 -> 0.091759135 | I34: =(D34-B34) -> 97810 | J34: =(D34/B34) -> 1.0962504 | K34: =(D34-B34)/B34 -> 0.096250359 | L34: =(E34-B34) -> 140692 | M34: =(E34/B34) -> 1.1384486 | N34: =(E34-B34)/B34 -> 0.13844858 | O34: =IFERROR(__xludf.DUMMYFUNCTION("SPARKLINE({F34; I34; L34},{""charttype"",""line"";""color"",""green""}) "),"") | P34: =IFERROR(__xludf.DUMMYFUNCTION("SPARKLINE({G34; J34; M34},{""charttype"",""column"";""color"",""green""})"),"") | Q34: =IFERROR(__xludf.DUMMYFUNCTION("SPARKLINE({H34;K34;N34},{""charttype"",""line"";""color"",""black""})"),"")
A37: Горизонтальный анализ (Ютэир) ОФП | F37: Изменения (базовый год 2020)
F38: Абсолютные отклонения | G38: Относительные отклонения | I38: Абсолютные отклонения | J38: Относительные отклонения | L38: Абсолютные отклонения | M38: Относительные отклонения
A39: на 31 декабря 202X года в миллионах рублей, если не указано иное | G39: Темп роста | H39: Темп прироста | J39: Темп роста | K39: Темп прироста | M39: Темп роста | N39: Темп прироста
B40: 2020 г. | C40: 2021 г. | D40: 2023 г. | E40: 2024г. | F40: 2021 г. | I40: 2023 г. | L40: 2024 г.
A41: АКТИВЫ
A42: Внеоборотные активы
...

Sheet Графики
A7: Выручка
B8: Аэрофлот | C8: Ютэер | D8: TurkishAirlines
A9: 2020 г. | B9: 302182 | C9: 56037 | D9: 498316
A10: 2021 г. | B10: 491733 | C10: 76752 | D10: 790764
A11: 2023 г. | B11: 612194 | C11: 99655 | D11: 1905722
A12: 2024 г. | B12: 856785 | C12: 113344 | D12: 2312238
O25: операционные расходы
A26: Темп роста выручки
B27: Аэрофлот | C27: Ютэер | D27: TurkishAirlines
A28: 2021 г. | B28: =(B10-B9)*100/B9 -> 62.727429 | C28: =(C10-C9)*100/C9 -> 36.966647 | D28: =(D10-D9)*100/D9 -> 58.687259
A29: 2023 г. | B29: =(B11-B10)*100/B10 -> 24.497237 | C29: =(C11-C10)*100/C10 -> 29.840265 | D29: =(D11-D10)*100/D10 -> 140.99757
A30: 2024 г. | B30: =(B12-B11)*100/B11 -> 39.953185 | C30: =(C12-C11)*100/C11 -> 13.736391 | D30: =(D12-D11)*100/D11 -> 21.331338
N42: Заёмные средства = Краткосрочные кредиты и займы + Долгосрочные кредиты и займы | V42: Собственный капитал
A43: Активы | O43: Аэрофлот | Q43: Ютэер | S43: TurkishAirlines | W43: Аэрофлот | X43: Ютэер | Y43: TurkishAirlines
B44: Аэрофлот | C44: Ютэер | D44: TurkishAirlines | N44: 2020 г. | O44: ='Аэрофлот'!B39+'Аэрофлот'!B44 -> 88635 | Q44: ='Ютэер'!B59+'Ютэер'!B47 -> 61496 | S44: =TurkishAirlines!B60+TurkishAirlines!B72+TurkishAirlines!B73 -> 399156 | V44: 2020 г. | W44: -115346 | X44: -4925 | Y44: 398342
A45: 2020 г. | B45: 1016204 | C45: 86106 | D45: 1889220 | N45: 2021 г. | O45: ='Аэрофлот'!C39+'Аэрофлот'!C44 -> 132268 | Q45: ='Ютэер'!C59+'Ютэер'!C47 -> 25152 | S45: =TurkishAirlines!C60+TurkishAirlines!C72+TurkishAirlines!C73 -> 344766 | V45: 2021 г. | W45: -146438 | X45: 10801 | Y45: 505938
A46: 2021 г. | B46: 1109450 | C46: 95458 | D46: 1963738 | N46: 2023 г. | O46: ='Аэрофлот'!D39+'Аэрофлот'!D44 -> 104368 | Q46: ='Ютэер'!D59+'Ютэер'!D47 -> 30744 | S46: =TurkishAirlines!D60+TurkishAirlines!D72+TurkishAirlines!D73 -> 221585 | V46: 2023 г. | W46: -98754 | X46: 23067 | Y46: 1416233
A47: 2023 г. | B47: 1114014 | C47: 123163 | D47: 3246061 | N47: 2024 г. | O47: ='Аэрофлот'!E39+'Аэрофлот'!E44 -> 60468 | Q47: ='Ютэер'!E59+'Ютэер'!E47 -> 31109 | S47: =TurkishAirlines!E60+TurkishAirlines!E72+TurkishAirlines!E73 -> 193290 | V47: 2024 г. | W47: -72497 | X47: 14445 | Y47: 1970028
A48: 2024 г. | B48: 1156896 | C48: 130350 | D48: 4046748
A52: Темп роста активов
B53: Аэрофлот | C53: Ютэер | D53: TurkishAirlines
A54: 2021 г. | B54: =(B46-B45)*100/B45 -> 9.1759135 | C54: =(C46-C45)*100/C45 -> 10.861032 | D54: =(D46-D45)*100/D45 -> 3.9443792
A55: 2023 г. | B55: =(B47-B46)*100/B46 -> 0.41137501 | C55: =(C47-C46)*100/C46 -> 29.023235 | D55: =(D47-D46)*100/D46 -> 65.300106
A56: 2024 г. | B56: =(B48-B47)*100/B47 -> 3.8493233 | C56: =(C48-C47)*100/C47 -> 5.8353564 | D56: =(D48-D47)*100/D47 -> 24.666419
A65: Чистая прибыль
B66: Аэрофлот | C66: Ютэер | D66: TurkishAirlines
A67: 2020 г. | B67: -123208 | C67: 3130 | D67: -61864
A68: 2021 г. | B68: -34460 | C68: 26825 | D68: 70966
A69: 2023 г. | B69: -14021 | C69: 2786 | D69: 547911
A70: 2024 г. | B70: 55020 | C70: -7015 | D70: 349350
A72: Темп роста чистой прибыли
B73: Аэрофлот | C73: Ютэер | D73: TurkishAirlines
A74: 2021 г. | B74: =(B68-B67)*100/abs(B67) -> 72.031037 | C74: =(C68-C67)*100/C67 -> 757.02875 | D74: =(D68-D67)*100/abs(D67) -> 214.71292
A75: 2023 г. | B75: =(B69-B68)*100/abs(B68) -> 59.312246 | C75: =(C69-C68)*100/C68 -> -89.614166 | D75: =(D69-D68)*100/D68 -> 672.07536
A76: 2024 г. | B76: =(B70-B69)*100/abs(B69) -> 492.41138 | C76: =(C70-C69)*100/C69 -> -351.79469 | D76: =(D70-D69)*100/D69 -> -36.239645
A92: Графики из Горизонтального анализа
A95: Денежные средства и их эквиваленты
A96: Год | B96: Аэрофлот | C96: Ютэир | D96: TurkishAirlines | E96: Общеотраслевые показатели
A97: 2020г | B97: 88944 | C97: 12679 | D97: 134014 | E97: 145171
A98: 2021г | B98: 74180 | C98: 7569 | D98: 198098 | E98: 161576
...
